Workbook

Sheet Info
B2: Metrics | C2: Definitions | D2: Metric Type
B3: MAIN_WEBSITE
B4: digital_active | C4: It's an online property that provides value and collects data.
B5: active_type | C5: Category used to identify if the digital property is a web platform or a mobile app.
B6: unique_visitors | C6: The total count of unique browsers or device identifiers interacting with digital assets, measured only upon explicit cookie consent. | D6: Performance Metrics
B7: visits | C7: A continuous session of user activity that expires after 30 minutes of inactivity or 12 hours of continuous browsing. | D7: Performance Metrics
B8: page_views | C8: The total count of times a specific page or screen is loaded or refreshed by users. | D8: Performance Metrics
B9: international_visits | C9: The percentage of total visits originating from users located outside of the brand's home country. | D9: Performance Metrics
B10: mobile_visits | C10: The percentage of total number of sessions originating from smartphones. | D10: Performance Metrics
B11: search_organic_visits | C11: The percentage of unpaid traffic coming directly from search engine results. | D11: Atribution Metrics
B12: social_organic_visits | C12: The percentage of unpaid traffic coming from social media (Instagram, WhatApp, Facebook, Tiktok, X,…) | D12: Atribution Metrics
B13: marketing_visits | C13: The percentage of the number of sessions that come from email, social paid, search paid, sms, app push, web push and display. | D13: Atribution Metrics
B14: other_channels_visits | C14: The percentage of the number of sessions that come from crosslinking, direct, brand and referral. | D14: Atribution Metrics
B15: consumption | C15: Pages Views / Visits | D15: Quality Metrics
B16: bounce_rate | C16: The percentage of visitors who leave your website or app after seeing only one page. | D16: Quality Metrics
B17: recurrence | C17: Visits / Unique Visitors | D17: Quality Metrics
... B19: logged_users | C19: Registered users who have accessed the digital assets while signed into their accounts. | D19: Quality Metrics
B20: ECOMMERCE
B21: digital_active | C21: It's an online property that provides value and collects data.
B22: active_type | C22: Category used to identify if the digital property is a web platform or a mobile app.
B23: unique_visitors | C23: The total count of unique browsers or device identifiers interacting with digital assets, measured only upon explicit cookie consent. | D23: Performance Metrics
B24: visits | C24: A continuous session of user activity that expires after 30 minutes of inactivity or 12 hours of continuous browsing. | D24: Performance Metrics
B25: purchases | C25: The total count of successful sales transactions completed during a specific period. | D25: Performance Metrics
B26: items | C26: The total count of specific products sold during a given period. | D26: Performance Metrics
B27: net_sales | C27: Total income from sales after removing the costs of returns and discounts. | D27: Performance Metrics
B28: search_organic_purchases | C28: The percentage of sales generated by unpaid traffic coming directly from search engine results. | D28: Atribution Metrics
B29: social_organic_purchases | C29: The percentage of sales generated by unpaid traffic coming from social media (Instagram, WhatApp, Facebook, Tiktok, X,…) | D29: Atribution Metrics
B30: marketing_purchases | C30: The percentage of sales generated by sessions that come from email, social paid, search paid, sms, app push, web push and display. | D30: Atribution Metrics
B31: other_channels_purchases | C31: The percentage of sales generated by sessions that come from crosslinking, direct, brand and referral. | D31: Atribution Metrics
B32: cart_value | C32: Net Sales / Purchases | D32: Quality Metrics
B33: product_views_rate | C33: The percentage of users who actually opened a product page out of all those who saw the product listed. | D33: Quality Metrics
B34: card_addition_rate | C34: The percentage of visitors who showed purchase intent by adding a product to their cart. | D34: Quality Metrics
... B37: recurrence | C37: Visits / Unique Visitors | D37: Quality Metrics
B38: STREAMING_WEBSITE
B39: digital_active | C39: It's an online property that provides value and collects data.
B40: active_type | C40: Category used to identify if the digital property is a web platform or a mobile app.
B41: unique_visitors | C41: The total count of unique browsers or device identifiers interacting with digital assets, measured only upon explicit cookie consent. | D41: Performance Metrics
B42: daily_users | C42: Number of unique visitors that the digital asset receives per day. | D42: Performance Metrics
B43: video_plays | C43: The total number of times that the videos started playing. | D43: Performance Metrics
B44: streamers | C44: The number of individual people who watched video content in the month. | D44: Performance Metrics
...

Sheet Main_Website
A1: month | B1: digital_active | C1: club | D1: active_type | E1: unique_visitors | F1: visits | G1: bounce_rate | H1: recurrence
A2: 42917 | B2: main_website | C2: masia_fc | D2: web | E2: 5428772 | F2: 9880365 | G2: 0.7304 | H2: 1.82
A3: 42948 | B3: main_website | C3: masia_fc | D3: web | E3: 5917361.5 | F3: 10183253 | G3: 0.55954556 | H3: 1.7209111
A4: 42979 | B4: main_website | C4: masia_fc | D4: web | E4: 4970583.6 | F4: 8219732.5 | G4: 0.57848378 | H4: 1.6536755
A5: 43009 | B5: main_website | C5: masia_fc | D5: web | E5: 4533734 | F5: 7527403.9 | G5: 0.6570279 | H5: 1.66031
A6: 43040 | B6: main_website | C6: masia_fc | D6: web | E6: 4840091.4 | F6: 8099953.3 | G6: 0.612581 | H6: 1.6735125
A7: 43070 | B7: main_website | C7: masia_fc | D7: web | E7: 6049032.3 | F7: 10061405 | G7: 0.54786541 | H7: 1.6633081
A8: 43101 | B8: main_website | C8: masia_fc | D8: web | E8: 5388011.8 | F8: 9326448.7 | G8: 0.57535778 | H8: 1.7309629
A9: 43132 | B9: main_website | C9: masia_fc | D9: web | E9: 5589513.6 | F9: 9021010.3 | G9: 0.60639169 | H9: 1.6139169
A10: 43160 | B10: main_website | C10: masia_fc | D10: web | E10: 4878585.2 | F10: 8001577.5 | G10: 0.56160858 | H10: 1.640143
A11: 43191 | B11: main_website | C11: masia_fc | D11: web | E11: 6049445.7 | F11: 9380870.6 | G11: 0.56176992 | H11: 1.5506992
A12: 43221 | B12: main_website | C12: masia_fc | D12: web | E12: 5141237 | F12: 8187609.5 | G12: 0.59972832 | H12: 1.5925369
A13: 43252 | B13: main_website | C13: masia_fc | D13: web | E13: 4267226.7 | F13: 6597071.9 | G13: 0.68799858 | H13: 1.5459858
... A516: 46023 | B516: main_website | C516: citizens | D516: web | E516: 2891312.7 | F516: 4632136 | G516: 0.72612525 | H516: 1.6020876

Sheet eCommerce
A1: month | B1: digital_active | C1: club | D1: active_type | E1: unique_visitors | F1: visits | G1: conversion_rate | H1: cart_value
A2: 42917 | B2: ecommerce | C2: masia_fc | D2: web | E2: 705740.36 | F2: 1271603 | G2: 0.014657664 | H2: 87.1728
A3: 42948 | B3: ecommerce | C3: masia_fc | D3: web | E3: 710083.38 | F3: 1099791.3 | G3: 0.012922416 | H3: 119.13311
A4: 42979 | B4: ecommerce | C4: masia_fc | D4: web | E4: 397646.69 | F4: 657578.6 | G4: 0.01602 | H4: 132.96775
A5: 43009 | B5: ecommerce | C5: masia_fc | D5: web | E5: 408036.06 | F5: 704565.01 | G5: 0.018986128 | H5: 133.57494
A6: 43040 | B6: ecommerce | C6: masia_fc | D6: web | E6: 677612.79 | F6: 1122653.5 | G6: 0.01877751 | H6: 101.3075
A7: 43070 | B7: ecommerce | C7: masia_fc | D7: web | E7: 1028335.5 | F7: 1710438.8 | G7: 0.026453466 | H7: 102.76662
A8: 43101 | B8: ecommerce | C8: masia_fc | D8: web | E8: 538801.18 | F8: 848706.83 | G8: 0.01306569 | H8: 114.91935
A9: 43132 | B9: ecommerce | C9: masia_fc | D9: web | E9: 503056.22 | F9: 876842.2 | G9: 0.012062624 | H9: 87.530474
A10: 43160 | B10: ecommerce | C10: masia_fc | D10: web | E10: 390286.82 | F10: 588916.11 | G10: 0.005635476 | H10: 85.990461
A11: 43191 | B11: ecommerce | C11: masia_fc | D11: web | E11: 544450.11 | F11: 759850.52 | G11: 0.00360126 | H11: 92.41849
A12: 43221 | B12: ecommerce | C12: masia_fc | D12: web | E12: 719773.18 | F12: 1134802.7 | G12: 0.01446003 | H12: 88.615865
A13: 43252 | B13: ecommerce | C13: masia_fc | D13: web | E13: 896117.61 | F13: 1399238.9 | G13: 0.01003136 | H13: 131.68013
... A516: 46023 | B516: ecommerce | C516: citizens | D516: web | E516: 289131.27 | F516: 430788.65 | G516: 0.013270218 | H516: 82.61924

Sheet Streaming
A1: month | B1: digital_active | C1: club | D1: active_type | E1: unique_visitors | F1: daily_users | G1: streamers_rate | H1: video_play_rate
A2: =Main_Website!A2 -> 42917 | B2: =Main_Website!B2 -> main_website | C2: =Main_Website!C2 -> masia_fc | D2: streaming | E2: 325726.32 | F2: 18208.101 | G2: 0.0559 | H2: 0.152
A3: =Main_Website!A3 -> 42948 | B3: =Main_Website!B3 -> main_website | C3: =Main_Website!C3 -> masia_fc | D3: streaming | E3: 710083.38 | F3: 192929.65 | G3: 0.2717 | H3: 0.504
A4: =Main_Website!A4 -> 42979 | B4: =Main_Website!B4 -> main_website | C4: =Main_Website!C4 -> masia_fc | D4: streaming | E4: 248529.18 | F4: 18565.13 | G4: 0.0747 | H4: 0.164
A5: =Main_Website!A5 -> 43009 | B5: =Main_Website!B5 -> main_website | C5: =Main_Website!C5 -> masia_fc | D5: streaming | E5: 408036.06 | F5: 54554.421 | G5: 0.1337 | H5: 0.246
A6: =Main_Website!A6 -> 43040 | B6: =Main_Website!B6 -> main_website | C6: =Main_Website!C6 -> masia_fc | D6: streaming | E6: 484009.14 | F6: 39349.943 | G6: 0.0813 | H6: 0.174
A7: =Main_Website!A7 -> 43070 | B7: =Main_Website!B7 -> main_website | C7: =Main_Website!C7 -> masia_fc | D7: streaming | E7: 302451.61 | F7: 22260.439 | G7: 0.0736 | H7: 0.207
A8: =Main_Website!A8 -> 43101 | B8: =Main_Website!B8 -> main_website | C8: =Main_Website!C8 -> masia_fc | D8: streaming | E8: 323280.71 | F8: 15840.755 | G8: 0.049 | H8: 0.204
A9: =Main_Website!A9 -> 43132 | B9: =Main_Website!B9 -> main_website | C9: =Main_Website!C9 -> masia_fc | D9: streaming | E9: 670741.63 | F9: 150044.9 | G9: 0.2237 | H9: 0.442
A10: =Main_Website!A10 -> 43160 | B10: =Main_Website!B10 -> main_website | C10: =Main_Website!C10 -> masia_fc | D10: streaming | E10: 292715.11 | F10: 23124.494 | G10: 0.079 | H10: 0.153
A11: =Main_Website!A11 -> 43191 | B11: =Main_Website!B11 -> main_website | C11: =Main_Website!C11 -> masia_fc | D11: streaming | E11: 483955.65 | F11: 46362.952 | G11: 0.0958 | H11: 0.344
A12: =Main_Website!A12 -> 43221 | B12: =Main_Website!B12 -> main_website | C12: =Main_Website!C12 -> masia_fc | D12: streaming | E12: 514123.7 | F12: 50229.886 | G12: 0.0977 | H12: 0.325
A13: =Main_Website!A13 -> 43252 | B13: =Main_Website!B13 -> main_website | C13: =Main_Website!C13 -> masia_fc | D13: streaming | E13: 298705.87 | F13: 20013.293 | G13: 0.067 | H13: 0.202
... A516: =Main_Website!A516 -> 46023 | B516: =Main_Website!B516 -> main_website | C516: =Main_Website!C516 -> citizens | D516: streaming | E516: 318044.39 | F516: 12912.602 | G516: 0.0406 | H516: 0.207

Sheet Fan_App
A1: month | B1: digital_active | C1: club | D1: active_type | E1: unique_visitors | F1: visits | G1: matchday_visits | H1: app_downloads | I1: recurrence | J1: heavy_users | K1: user_rating
A2: =Main_Website!A2 -> 42917 | B2: fan_app | C2: =Main_Website!C2 -> masia_fc | D2: app | E2: 91832.467 | F2: 322126.56 | G2: 17602.934 | H2: 48671.207 | I2: 3.5077633 | J2: 0.113 | K2: 4.4
A3: =Main_Website!A3 -> 42948 | B3: fan_app | C3: =Main_Website!C3 -> masia_fc | D3: app | E3: 116504.64 | F3: 391009.89 | G3: 92687.173 | H3: 66407.647 | I3: 3.3561743 | J3: 0.096 | K3: 4.46
A4: =Main_Website!A4 -> 42979 | B4: fan_app | C4: =Main_Website!C4 -> masia_fc | D4: app | E4: 108845.61 | F4: 341397.05 | G4: 182051.68 | H4: 74015.014 | I4: 3.1365257 | J4: 0.066 | K4: 4.417
A5: =Main_Website!A5 -> 43009 | B5: fan_app | C5: =Main_Website!C5 -> masia_fc | D5: app | E5: 90353.826 | F5: 278813.3 | G5: 167659.8 | H5: 54212.295 | I5: 3.085794 | J5: 0.052 | K5: 4.38
A6: =Main_Website!A6 -> 43040 | B6: fan_app | C6: =Main_Website!C6 -> masia_fc | D6: app | E6: 83868.457 | F6: 295470.82 | G6: 168313.18 | H6: 48643.705 | I6: 3.5230268 | J6: 0.095 | K6: 4.406
A7: =Main_Website!A7 -> 43070 | B7: fan_app | C7: =Main_Website!C7 -> masia_fc | D7: app | E7: 111761.5 | F7: 377730.78 | G7: 225966.49 | H7: 55880.752 | I7: 3.3797933 | J7: 0.088 | K7: 4.498
A8: =Main_Website!A8 -> 43101 | B8: fan_app | C8: =Main_Website!C8 -> masia_fc | D8: app | E8: 93791.559 | F8: 315121.55 | G8: 188101.85 | H8: 46895.779 | I8: 3.3598072 | J8: 0.079 | K8: 4.575
A9: =Main_Website!A9 -> 43132 | B9: fan_app | C9: =Main_Website!C9 -> masia_fc | D9: app | E9: 117221.77 | F9: 405181.98 | G9: 297414.43 | H9: 69160.844 | I9: 3.4565421 | J9: 0.098 | K9: 4.653
A10: =Main_Website!A10 -> 43160 | B10: fan_app | C10: =Main_Website!C10 -> masia_fc | D10: app | E10: 96802.821 | F10: 295219.12 | G10: 177747 | H10: 67761.974 | I10: 3.0496954 | J10: 0.036 | K10: 4.553
A11: =Main_Website!A11 -> 43191 | B11: fan_app | C11: =Main_Website!C11 -> masia_fc | D11: app | E11: 43916.585 | F11: 125972.74 | G11: 75364.954 | H11: 26349.951 | I11: 2.8684548 | J11: 0.056 | K11: 4.513
A12: =Main_Website!A12 -> 43221 | B12: fan_app | C12: =Main_Website!C12 -> masia_fc | D12: app | E12: 36064.754 | F12: 110388.34 | G12: 76851.478 | H12: 24524.033 | I12: 3.0608371 | J12: 0.061 | K12: 4.467
A13: =Main_Website!A13 -> 43252 | B13: fan_app | C13: =Main_Website!C13 -> masia_fc | D13: app | E13: 84673.234 | F13: 265552.82 | G13: 141224.6 | H13: 50803.94 | I13: 3.1362073 | J13: 0.068 | K13: 4.387
... A516: =Main_Website!A516 -> 46023 | B516: fan_app | C516: =Main_Website!C516 -> citizens | D516: app | E516: 69451.622 | F516: 220083.9 | G516: 120964.71 | H516: 47227.103 | I516: 3.1688806 | J516: 0.069 | K516: 4.211
